https://stackoverflow.com/questions/46355998/typeerror-nonetype-object-is-not-subscriptable-followed-by-attributeerror-n




[08/Feb/2019 05:53:05] "GET /static/images/default_image.png HTTP/1.1" 200 150
Traceback (most recent call last):
  File "C:\Python36\lib\wsgiref\handlers.py", line 138, in run
    self.finish_response()
  File "C:\Python36\lib\wsgiref\handlers.py", line 180, in finish_response
    self.write(data)
  File "C:\Python36\lib\wsgiref\handlers.py", line 274, in write
    self.send_headers()
  File "C:\Python36\lib\wsgiref\handlers.py", line 332, in send_headers
    self.send_preamble()
  File "C:\Python36\lib\wsgiref\handlers.py", line 255, in send_preamble
    ('Date: %s\r\n' % format_date_time(time.time())).encode('iso-8859-1')
  File "C:\Python36\lib\wsgiref\handlers.py", line 453, in _write
    result = self.stdout.write(data)
  File "C:\Python36\lib\socketserver.py", line 775, in write
    self._sock.sendall(b)
ConnectionAbortedError: [WinError 10053] 您的主机中的软件中止了一个已建立的连接。
[08/Feb/2019 05:53:05] "GET /static/images/default_image.png HTTP/1.1" 500 59
----------------------------------------
Exception happened during processing of request from ('127.0.0.1', 55311)
Traceback (most recent call last):
  File "C:\Python36\lib\wsgiref\handlers.py", line 138, in run
    self.finish_response()
  File "C:\Python36\lib\wsgiref\handlers.py", line 180, in finish_response
    self.write(data)
  File "C:\Python36\lib\wsgiref\handlers.py", line 274, in write
    self.send_headers()
  File "C:\Python36\lib\wsgiref\handlers.py", line 332, in send_headers
    self.send_preamble()
  File "C:\Python36\lib\wsgiref\handlers.py", line 255, in send_preamble
    ('Date: %s\r\n' % format_date_time(time.time())).encode('iso-8859-1')
  File "C:\Python36\lib\wsgiref\handlers.py", line 453, in _write
    result = self.stdout.write(data)
  File "C:\Python36\lib\socketserver.py", line 775, in write
    self._sock.sendall(b)
ConnectionAbortedError: [WinError 10053] 您的主机中的软件中止了一个已建立的连接。

During handling of the above exception, another exception occurred:

Traceback (most recent call last):
  File "C:\Python36\lib\wsgiref\handlers.py", line 141, in run
    self.handle_error()
  File "C:\Python36\lib\site-packages\django\core\servers\basehttp.py", line 116, in handle_error
    super().handle_error()
  File "C:\Python36\lib\wsgiref\handlers.py", line 368, in handle_error
    self.finish_response()
  File "C:\Python36\lib\wsgiref\handlers.py", line 180, in finish_response
    self.write(data)
  File "C:\Python36\lib\wsgiref\handlers.py", line 274, in write
    self.send_headers()
  File "C:\Python36\lib\wsgiref\handlers.py", line 331, in send_headers
    if not self.origin_server or self.client_is_modern():
  File "C:\Python36\lib\wsgiref\handlers.py", line 344, in client_is_modern
    return self.environ['SERVER_PROTOCOL'].upper() != 'HTTP/0.9'
TypeError: 'NoneType' object is not subscriptable

During handling of the above exception, another exception occurred:

Traceback (most recent call last):
  File "C:\Python36\lib\socketserver.py", line 639, in process_request_thread
    self.finish_request(request, client_address)
  File "C:\Python36\lib\socketserver.py", line 361, in finish_request
    self.RequestHandlerClass(request, client_address, self)
  File "C:\Python36\lib\socketserver.py", line 696, in __init__
    self.handle()
  File "C:\Python36\lib\site-packages\django\core\servers\basehttp.py", line 171, in handle
    self.handle_one_request()
  File "C:\Python36\lib\site-packages\django\core\servers\basehttp.py", line 194, in handle_one_request
    handler.run(self.server.get_app())
  File "C:\Python36\lib\wsgiref\handlers.py", line 144, in run
    self.close()
  File "C:\Python36\lib\site-packages\django\core\servers\basehttp.py", line 111, in close
    super().close()
  File "C:\Python36\lib\wsgiref\simple_server.py", line 35, in close
    self.status.split(' ',1)[0], self.bytes_sent
AttributeError: 'NoneType' object has no attribute 'split'
----------------------------------------

